{
 "cells": [
  {
   "cell_type": "code",
   "execution_count": 1,
   "id": "d3675e01",
   "metadata": {},
   "outputs": [
    {
     "name": "stderr",
     "output_type": "stream",
     "text": [
      "Using TensorFlow backend.\n"
     ]
    }
   ],
   "source": [
    "import os\n",
    "import cv2\n",
    "import numpy as np\n",
    "\n",
    "from imutils import paths\n",
    "from sklearn.preprocessing import LabelBinarizer\n",
    "from sklearn.model_selection import train_test_split\n",
    "from keras.preprocessing.image import ImageDataGenerator\n"
   ]
  },
  {
   "cell_type": "code",
   "execution_count": 2,
   "id": "f5e86b58",
   "metadata": {},
   "outputs": [],
   "source": [
    "data_path = \"KD_data\"\n",
    "\n",
    "output_model = r\"KD_classification_model\\classification_model\"\n",
    "output_label_binarizer = r\"KD_classification_model\\label_binarizer\"\n",
    "\n",
    "#output_model = r\"kill_death_classification_model\\classification_model\"\n",
    "#output_label_binarizer = r\"kill_death_classification_model\\label_binarizer\""
   ]
  },
  {
   "cell_type": "code",
   "execution_count": null,
   "id": "9d832f28",
   "metadata": {
    "scrolled": true
   },
   "outputs": [
    {
     "name": "stdout",
     "output_type": "stream",
     "text": [
      "Images are being loaded...\n"
     ]
    }
   ],
   "source": [
    "KD_labels = set(['kill', 'death'])\n",
    "\n",
    "print('Images are being loaded...')\n",
    "\n",
    "path_to_images = list(paths.list_images(data_path))\n",
    "data = []\n",
    "labels = []\n",
    "\n",
    "for images in path_to_images:\n",
    "    label = images.split(os.path.sep)[-2]\n",
    "    if label not in KD_labels:\n",
    "        continue\n",
    "    image = cv2.imread(images)\n",
    "    image = cv2.cvtColor(image, cv2.COLOR_BGR2RGB)\n",
    "    image = cv2.resize(image, (224,224))\n",
    "    \n",
    "    data.append(image)\n",
    "    labels.append(label)\n",
    "\n",
    "\n",
    "print(\"Done.\")"
   ]
  },
  {
   "cell_type": "code",
   "execution_count": null,
   "id": "a74208b6",
   "metadata": {},
   "outputs": [],
   "source": [
    "data = np.array(data)\n",
    "labels = np.array(labels)\n",
    "\n",
    "print(labels)"
   ]
  },
  {
   "cell_type": "code",
   "execution_count": null,
   "id": "05aee511",
   "metadata": {},
   "outputs": [],
   "source": [
    "# Binarize the classification labels\n",
    "\n",
    "lb = LabelBinarizer()\n",
    "labels = lb.fit_transform(labels)"
   ]
  },
  {
   "cell_type": "code",
   "execution_count": 5,
   "id": "577d0879",
   "metadata": {},
   "outputs": [],
   "source": [
    "(X_train, X_test, Y_train, Y_test) = train_test_split(data, labels, test_size=0.25, stratify=labels, random_state=42)"
   ]
  },
  {
   "cell_type": "code",
   "execution_count": 6,
   "id": "178206a0",
   "metadata": {},
   "outputs": [],
   "source": [
    "train_Aug = ImageDataGenerator(\n",
    "    rotation_range=30,\n",
    "    zoom_range=0.15,\n",
    "    width_shift_range=0.2,\n",
    "    height_shift_range=0.2,\n",
    "    shear_range=0.15,\n",
    "    horizontal_flip=True,\n",
    "    fill_mode=\"nearest\"\n",
    ")\n",
    "\n",
    "valid_Aug = ImageDataGenerator()\n",
    "mean = np.array([123.68, 116.779, 103.939], dtype=\"float32\")\n",
    "\n",
    "train_Aug.mean = mean\n",
    "valid_Aug.mean = mean"
   ]
  },
  {
   "cell_type": "code",
   "execution_count": 7,
   "id": "2bd802a7",
   "metadata": {},
   "outputs": [],
   "source": [
    "# Model Libraries\n",
    "\n",
    "from keras.applications import ResNet50\n",
    "\n",
    "from keras.layers import Input\n",
    "from keras.layers.pooling import AveragePooling2D\n",
    "from keras.layers.core import Flatten, Dense, Dropout\n",
    "from keras.models import Model\n"
   ]
  },
  {
   "cell_type": "code",
   "execution_count": 8,
   "id": "d40c0bdf",
   "metadata": {},
   "outputs": [
    {
     "name": "stderr",
     "output_type": "stream",
     "text": [
      "C:\\Users\\HP\\Anaconda3\\lib\\site-packages\\keras_applications\\resnet50.py:265: UserWarning: The output shape of `ResNet50(include_top=False)` has been changed since Keras 2.2.0.\n",
      "  warnings.warn('The output shape of `ResNet50(include_top=False)` '\n"
     ]
    }
   ],
   "source": [
    "# Model\n",
    "\n",
    "base_model = ResNet50(weights=\"imagenet\", include_top=False, input_tensor=Input(shape=(224,224,3)))\n",
    "\n",
    "head_model = base_model.output\n",
    "head_model = AveragePooling2D(pool_size=(7,7))(head_model)\n",
    "head_model = Flatten(name=\"flatten\")(head_model)\n",
    "head_model = Dense(512, activation='relu')(head_model)\n",
    "head_model = Dropout(0.5)(head_model)\n",
    "head_model = Dense(len(lb.classes_), activation='softmax')(head_model)\n",
    "\n",
    "model = Model(inputs=base_model.input, outputs=head_model)\n",
    "epochs = 5\n",
    "\n",
    "for b_m_layers in base_model.layers:\n",
    "    b_m_layers.trainable = False\n"
   ]
  },
  {
   "cell_type": "code",
   "execution_count": 9,
   "id": "ff526de6",
   "metadata": {},
   "outputs": [],
   "source": [
    "from keras.optimizers import SGD\n",
    "\n",
    "opt = SGD(lr=0.0001, momentum=0.9, decay=1e-4/epochs)"
   ]
  },
  {
   "cell_type": "code",
   "execution_count": 10,
   "id": "f879a014",
   "metadata": {},
   "outputs": [],
   "source": [
    "model.compile(loss='categorical_crossentropy', optimizer=opt, metrics=['accuracy'])"
   ]
  },
  {
   "cell_type": "code",
   "execution_count": null,
   "id": "8f548a4f",
   "metadata": {},
   "outputs": [
    {
     "name": "stdout",
     "output_type": "stream",
     "text": [
      "Epoch 1/5\n"
     ]
    },
    {
     "name": "stderr",
     "output_type": "stream",
     "text": [
      "ERROR:root:Internal Python error in the inspect module.\n",
      "Below is the traceback from this internal error.\n",
      "\n",
      "ERROR:root:Internal Python error in the inspect module.\n",
      "Below is the traceback from this internal error.\n",
      "\n",
      "ERROR:root:Internal Python error in the inspect module.\n",
      "Below is the traceback from this internal error.\n",
      "\n"
     ]
    },
    {
     "name": "stdout",
     "output_type": "stream",
     "text": [
      "Traceback (most recent call last):\n",
      "  File \"C:\\Users\\HP\\Anaconda3\\lib\\site-packages\\IPython\\core\\interactiveshell.py\", line 3437, in run_code\n",
      "    exec(code_obj, self.user_global_ns, self.user_ns)\n",
      "  File \"<ipython-input-11-cb6698a98a99>\", line 6, in <module>\n",
      "    epochs=epochs\n",
      "  File \"C:\\Users\\HP\\Anaconda3\\lib\\site-packages\\keras\\legacy\\interfaces.py\", line 91, in wrapper\n",
      "    return func(*args, **kwargs)\n",
      "  File \"C:\\Users\\HP\\Anaconda3\\lib\\site-packages\\keras\\engine\\training.py\", line 1732, in fit_generator\n",
      "    initial_epoch=initial_epoch)\n",
      "  File \"C:\\Users\\HP\\Anaconda3\\lib\\site-packages\\keras\\engine\\training_generator.py\", line 220, in fit_generator\n",
      "    reset_metrics=False)\n",
      "  File \"C:\\Users\\HP\\Anaconda3\\lib\\site-packages\\keras\\engine\\training.py\", line 1508, in train_on_batch\n",
      "    class_weight=class_weight)\n",
      "  File \"C:\\Users\\HP\\Anaconda3\\lib\\site-packages\\keras\\engine\\training.py\", line 621, in _standardize_user_data\n",
      "    exception_prefix='target')\n",
      "  File \"C:\\Users\\HP\\Anaconda3\\lib\\site-packages\\keras\\engine\\training_utils.py\", line 145, in standardize_input_data\n",
      "    str(data_shape))\n",
      "ValueError: Error when checking target: expected dense_2 to have shape (2,) but got array with shape (1,)\n",
      "\n",
      "During handling of the above exception, another exception occurred:\n",
      "\n",
      "Traceback (most recent call last):\n",
      "  File \"C:\\Users\\HP\\Anaconda3\\lib\\site-packages\\IPython\\core\\interactiveshell.py\", line 2061, in showtraceback\n",
      "    stb = value._render_traceback_()\n",
      "AttributeError: 'ValueError' object has no attribute '_render_traceback_'\n",
      "\n",
      "During handling of the above exception, another exception occurred:\n",
      "\n",
      "Traceback (most recent call last):\n",
      "  File \"C:\\Users\\HP\\Anaconda3\\lib\\site-packages\\IPython\\core\\ultratb.py\", line 1101, in get_records\n",
      "    return _fixed_getinnerframes(etb, number_of_lines_of_context, tb_offset)\n",
      "  File \"C:\\Users\\HP\\Anaconda3\\lib\\site-packages\\IPython\\core\\ultratb.py\", line 248, in wrapped\n",
      "    return f(*args, **kwargs)\n",
      "  File \"C:\\Users\\HP\\Anaconda3\\lib\\site-packages\\IPython\\core\\ultratb.py\", line 281, in _fixed_getinnerframes\n",
      "    records = fix_frame_records_filenames(inspect.getinnerframes(etb, context))\n",
      "  File \"C:\\Users\\HP\\Anaconda3\\lib\\inspect.py\", line 1502, in getinnerframes\n",
      "    frameinfo = (tb.tb_frame,) + getframeinfo(tb, context)\n",
      "  File \"C:\\Users\\HP\\Anaconda3\\lib\\inspect.py\", line 1460, in getframeinfo\n",
      "    filename = getsourcefile(frame) or getfile(frame)\n",
      "  File \"C:\\Users\\HP\\Anaconda3\\lib\\inspect.py\", line 696, in getsourcefile\n",
      "    if getattr(getmodule(object, filename), '__loader__', None) is not None:\n",
      "  File \"C:\\Users\\HP\\Anaconda3\\lib\\inspect.py\", line 733, in getmodule\n",
      "    if ismodule(module) and hasattr(module, '__file__'):\n",
      "  File \"C:\\Users\\HP\\Anaconda3\\lib\\site-packages\\tensorflow\\__init__.py\", line 50, in __getattr__\n",
      "    module = self._load()\n",
      "  File \"C:\\Users\\HP\\Anaconda3\\lib\\site-packages\\tensorflow\\__init__.py\", line 44, in _load\n",
      "    module = _importlib.import_module(self.__name__)\n",
      "  File \"C:\\Users\\HP\\Anaconda3\\lib\\importlib\\__init__.py\", line 127, in import_module\n",
      "    return _bootstrap._gcd_import(name[level:], package, level)\n",
      "  File \"<frozen importlib._bootstrap>\", line 1006, in _gcd_import\n",
      "  File \"<frozen importlib._bootstrap>\", line 983, in _find_and_load\n",
      "  File \"<frozen importlib._bootstrap>\", line 965, in _find_and_load_unlocked\n",
      "ModuleNotFoundError: No module named 'tensorflow_core.estimator'\n",
      "Traceback (most recent call last):\n",
      "  File \"C:\\Users\\HP\\Anaconda3\\lib\\site-packages\\IPython\\core\\interactiveshell.py\", line 3437, in run_code\n",
      "    exec(code_obj, self.user_global_ns, self.user_ns)\n",
      "  File \"<ipython-input-11-cb6698a98a99>\", line 6, in <module>\n",
      "    epochs=epochs\n",
      "  File \"C:\\Users\\HP\\Anaconda3\\lib\\site-packages\\keras\\legacy\\interfaces.py\", line 91, in wrapper\n",
      "    return func(*args, **kwargs)\n",
      "  File \"C:\\Users\\HP\\Anaconda3\\lib\\site-packages\\keras\\engine\\training.py\", line 1732, in fit_generator\n",
      "    initial_epoch=initial_epoch)\n",
      "  File \"C:\\Users\\HP\\Anaconda3\\lib\\site-packages\\keras\\engine\\training_generator.py\", line 220, in fit_generator\n",
      "    reset_metrics=False)\n",
      "  File \"C:\\Users\\HP\\Anaconda3\\lib\\site-packages\\keras\\engine\\training.py\", line 1508, in train_on_batch\n",
      "    class_weight=class_weight)\n",
      "  File \"C:\\Users\\HP\\Anaconda3\\lib\\site-packages\\keras\\engine\\training.py\", line 621, in _standardize_user_data\n",
      "    exception_prefix='target')\n",
      "  File \"C:\\Users\\HP\\Anaconda3\\lib\\site-packages\\keras\\engine\\training_utils.py\", line 145, in standardize_input_data\n",
      "    str(data_shape))\n",
      "ValueError: Error when checking target: expected dense_2 to have shape (2,) but got array with shape (1,)\n",
      "\n",
      "During handling of the above exception, another exception occurred:\n",
      "\n",
      "Traceback (most recent call last):\n",
      "  File \"C:\\Users\\HP\\Anaconda3\\lib\\site-packages\\IPython\\core\\interactiveshell.py\", line 2061, in showtraceback\n",
      "    stb = value._render_traceback_()\n",
      "AttributeError: 'ValueError' object has no attribute '_render_traceback_'\n",
      "\n",
      "During handling of the above exception, another exception occurred:\n",
      "\n",
      "Traceback (most recent call last):\n",
      "  File \"C:\\Users\\HP\\Anaconda3\\lib\\site-packages\\IPython\\core\\interactiveshell.py\", line 3357, in run_ast_nodes\n",
      "    if (await self.run_code(code, result,  async_=asy)):\n",
      "  File \"C:\\Users\\HP\\Anaconda3\\lib\\site-packages\\IPython\\core\\interactiveshell.py\", line 3454, in run_code\n",
      "    self.showtraceback(running_compiled_code=True)\n",
      "  File \"C:\\Users\\HP\\Anaconda3\\lib\\site-packages\\IPython\\core\\interactiveshell.py\", line 2064, in showtraceback\n",
      "    value, tb, tb_offset=tb_offset)\n",
      "  File \"C:\\Users\\HP\\Anaconda3\\lib\\site-packages\\IPython\\core\\ultratb.py\", line 1368, in structured_traceback\n",
      "    self, etype, value, tb, tb_offset, number_of_lines_of_context)\n",
      "  File \"C:\\Users\\HP\\Anaconda3\\lib\\site-packages\\IPython\\core\\ultratb.py\", line 1268, in structured_traceback\n",
      "    self, etype, value, tb, tb_offset, number_of_lines_of_context\n",
      "  File \"C:\\Users\\HP\\Anaconda3\\lib\\site-packages\\IPython\\core\\ultratb.py\", line 1125, in structured_traceback\n",
      "    tb_offset)\n",
      "  File \"C:\\Users\\HP\\Anaconda3\\lib\\site-packages\\IPython\\core\\ultratb.py\", line 1082, in format_exception_as_a_whole\n",
      "    last_unique, recursion_repeat = find_recursion(orig_etype, evalue, records)\n",
      "  File \"C:\\Users\\HP\\Anaconda3\\lib\\site-packages\\IPython\\core\\ultratb.py\", line 382, in find_recursion\n",
      "    return len(records), 0\n",
      "TypeError: object of type 'NoneType' has no len()\n",
      "\n",
      "During handling of the above exception, another exception occurred:\n",
      "\n",
      "Traceback (most recent call last):\n",
      "  File \"C:\\Users\\HP\\Anaconda3\\lib\\site-packages\\IPython\\core\\interactiveshell.py\", line 2061, in showtraceback\n",
      "    stb = value._render_traceback_()\n",
      "AttributeError: 'TypeError' object has no attribute '_render_traceback_'\n",
      "\n",
      "During handling of the above exception, another exception occurred:\n",
      "\n",
      "Traceback (most recent call last):\n",
      "  File \"C:\\Users\\HP\\Anaconda3\\lib\\site-packages\\IPython\\core\\ultratb.py\", line 1101, in get_records\n",
      "    return _fixed_getinnerframes(etb, number_of_lines_of_context, tb_offset)\n",
      "  File \"C:\\Users\\HP\\Anaconda3\\lib\\site-packages\\IPython\\core\\ultratb.py\", line 248, in wrapped\n",
      "    return f(*args, **kwargs)\n",
      "  File \"C:\\Users\\HP\\Anaconda3\\lib\\site-packages\\IPython\\core\\ultratb.py\", line 281, in _fixed_getinnerframes\n",
      "    records = fix_frame_records_filenames(inspect.getinnerframes(etb, context))\n",
      "  File \"C:\\Users\\HP\\Anaconda3\\lib\\inspect.py\", line 1502, in getinnerframes\n",
      "    frameinfo = (tb.tb_frame,) + getframeinfo(tb, context)\n",
      "  File \"C:\\Users\\HP\\Anaconda3\\lib\\inspect.py\", line 1460, in getframeinfo\n",
      "    filename = getsourcefile(frame) or getfile(frame)\n",
      "  File \"C:\\Users\\HP\\Anaconda3\\lib\\inspect.py\", line 696, in getsourcefile\n",
      "    if getattr(getmodule(object, filename), '__loader__', None) is not None:\n",
      "  File \"C:\\Users\\HP\\Anaconda3\\lib\\inspect.py\", line 733, in getmodule\n",
      "    if ismodule(module) and hasattr(module, '__file__'):\n",
      "  File \"C:\\Users\\HP\\Anaconda3\\lib\\site-packages\\tensorflow\\__init__.py\", line 50, in __getattr__\n",
      "    module = self._load()\n",
      "  File \"C:\\Users\\HP\\Anaconda3\\lib\\site-packages\\tensorflow\\__init__.py\", line 44, in _load\n",
      "    module = _importlib.import_module(self.__name__)\n",
      "  File \"C:\\Users\\HP\\Anaconda3\\lib\\importlib\\__init__.py\", line 127, in import_module\n",
      "    return _bootstrap._gcd_import(name[level:], package, level)\n",
      "  File \"<frozen importlib._bootstrap>\", line 1006, in _gcd_import\n",
      "  File \"<frozen importlib._bootstrap>\", line 983, in _find_and_load\n",
      "  File \"<frozen importlib._bootstrap>\", line 965, in _find_and_load_unlocked\n",
      "ModuleNotFoundError: No module named 'tensorflow_core.estimator'\n",
      "Traceback (most recent call last):\n",
      "  File \"C:\\Users\\HP\\Anaconda3\\lib\\site-packages\\IPython\\core\\interactiveshell.py\", line 3437, in run_code\n",
      "    exec(code_obj, self.user_global_ns, self.user_ns)\n",
      "  File \"<ipython-input-11-cb6698a98a99>\", line 6, in <module>\n",
      "    epochs=epochs\n",
      "  File \"C:\\Users\\HP\\Anaconda3\\lib\\site-packages\\keras\\legacy\\interfaces.py\", line 91, in wrapper\n",
      "    return func(*args, **kwargs)\n",
      "  File \"C:\\Users\\HP\\Anaconda3\\lib\\site-packages\\keras\\engine\\training.py\", line 1732, in fit_generator\n",
      "    initial_epoch=initial_epoch)\n",
      "  File \"C:\\Users\\HP\\Anaconda3\\lib\\site-packages\\keras\\engine\\training_generator.py\", line 220, in fit_generator\n",
      "    reset_metrics=False)\n",
      "  File \"C:\\Users\\HP\\Anaconda3\\lib\\site-packages\\keras\\engine\\training.py\", line 1508, in train_on_batch\n",
      "    class_weight=class_weight)\n",
      "  File \"C:\\Users\\HP\\Anaconda3\\lib\\site-packages\\keras\\engine\\training.py\", line 621, in _standardize_user_data\n",
      "    exception_prefix='target')\n",
      "  File \"C:\\Users\\HP\\Anaconda3\\lib\\site-packages\\keras\\engine\\training_utils.py\", line 145, in standardize_input_data\n",
      "    str(data_shape))\n",
      "ValueError: Error when checking target: expected dense_2 to have shape (2,) but got array with shape (1,)\n",
      "\n",
      "During handling of the above exception, another exception occurred:\n",
      "\n",
      "Traceback (most recent call last):\n",
      "  File \"C:\\Users\\HP\\Anaconda3\\lib\\site-packages\\IPython\\core\\interactiveshell.py\", line 2061, in showtraceback\n",
      "    stb = value._render_traceback_()\n",
      "AttributeError: 'ValueError' object has no attribute '_render_traceback_'\n",
      "\n",
      "During handling of the above exception, another exception occurred:\n",
      "\n",
      "Traceback (most recent call last):\n",
      "  File \"C:\\Users\\HP\\Anaconda3\\lib\\site-packages\\IPython\\core\\interactiveshell.py\", line 3357, in run_ast_nodes\n",
      "    if (await self.run_code(code, result,  async_=asy)):\n",
      "  File \"C:\\Users\\HP\\Anaconda3\\lib\\site-packages\\IPython\\core\\interactiveshell.py\", line 3454, in run_code\n",
      "    self.showtraceback(running_compiled_code=True)\n",
      "  File \"C:\\Users\\HP\\Anaconda3\\lib\\site-packages\\IPython\\core\\interactiveshell.py\", line 2064, in showtraceback\n",
      "    value, tb, tb_offset=tb_offset)\n",
      "  File \"C:\\Users\\HP\\Anaconda3\\lib\\site-packages\\IPython\\core\\ultratb.py\", line 1368, in structured_traceback\n",
      "    self, etype, value, tb, tb_offset, number_of_lines_of_context)\n",
      "  File \"C:\\Users\\HP\\Anaconda3\\lib\\site-packages\\IPython\\core\\ultratb.py\", line 1268, in structured_traceback\n",
      "    self, etype, value, tb, tb_offset, number_of_lines_of_context\n",
      "  File \"C:\\Users\\HP\\Anaconda3\\lib\\site-packages\\IPython\\core\\ultratb.py\", line 1125, in structured_traceback\n",
      "    tb_offset)\n",
      "  File \"C:\\Users\\HP\\Anaconda3\\lib\\site-packages\\IPython\\core\\ultratb.py\", line 1082, in format_exception_as_a_whole\n",
      "    last_unique, recursion_repeat = find_recursion(orig_etype, evalue, records)\n",
      "  File \"C:\\Users\\HP\\Anaconda3\\lib\\site-packages\\IPython\\core\\ultratb.py\", line 382, in find_recursion\n",
      "    return len(records), 0\n",
      "TypeError: object of type 'NoneType' has no len()\n",
      "\n",
      "During handling of the above exception, another exception occurred:\n",
      "\n",
      "Traceback (most recent call last):\n",
      "  File \"C:\\Users\\HP\\Anaconda3\\lib\\site-packages\\IPython\\core\\interactiveshell.py\", line 2061, in showtraceback\n",
      "    stb = value._render_traceback_()\n",
      "AttributeError: 'TypeError' object has no attribute '_render_traceback_'\n",
      "\n",
      "During handling of the above exception, another exception occurred:\n",
      "\n",
      "Traceback (most recent call last):\n",
      "  File \"C:\\Users\\HP\\Anaconda3\\lib\\site-packages\\IPython\\core\\interactiveshell.py\", line 2940, in _run_cell\n",
      "    return runner(coro)\n",
      "  File \"C:\\Users\\HP\\Anaconda3\\lib\\site-packages\\IPython\\core\\async_helpers.py\", line 68, in _pseudo_sync_runner\n",
      "    coro.send(None)\n",
      "  File \"C:\\Users\\HP\\Anaconda3\\lib\\site-packages\\IPython\\core\\interactiveshell.py\", line 3166, in run_cell_async\n",
      "    interactivity=interactivity, compiler=compiler, result=result)\n",
      "  File \"C:\\Users\\HP\\Anaconda3\\lib\\site-packages\\IPython\\core\\interactiveshell.py\", line 3376, in run_ast_nodes\n",
      "    self.showtraceback()\n",
      "  File \"C:\\Users\\HP\\Anaconda3\\lib\\site-packages\\IPython\\core\\interactiveshell.py\", line 2064, in showtraceback\n",
      "    value, tb, tb_offset=tb_offset)\n",
      "  File \"C:\\Users\\HP\\Anaconda3\\lib\\site-packages\\IPython\\core\\ultratb.py\", line 1368, in structured_traceback\n",
      "    self, etype, value, tb, tb_offset, number_of_lines_of_context)\n",
      "  File \"C:\\Users\\HP\\Anaconda3\\lib\\site-packages\\IPython\\core\\ultratb.py\", line 1268, in structured_traceback\n",
      "    self, etype, value, tb, tb_offset, number_of_lines_of_context\n",
      "  File \"C:\\Users\\HP\\Anaconda3\\lib\\site-packages\\IPython\\core\\ultratb.py\", line 1143, in structured_traceback\n",
      "    chained_exceptions_tb_offset)\n",
      "  File \"C:\\Users\\HP\\Anaconda3\\lib\\site-packages\\IPython\\core\\ultratb.py\", line 1082, in format_exception_as_a_whole\n",
      "    last_unique, recursion_repeat = find_recursion(orig_etype, evalue, records)\n",
      "  File \"C:\\Users\\HP\\Anaconda3\\lib\\site-packages\\IPython\\core\\ultratb.py\", line 382, in find_recursion\n",
      "    return len(records), 0\n",
      "TypeError: object of type 'NoneType' has no len()\n",
      "\n",
      "During handling of the above exception, another exception occurred:\n",
      "\n",
      "Traceback (most recent call last):\n",
      "  File \"C:\\Users\\HP\\Anaconda3\\lib\\site-packages\\IPython\\core\\interactiveshell.py\", line 2061, in showtraceback\n",
      "    stb = value._render_traceback_()\n",
      "AttributeError: 'TypeError' object has no attribute '_render_traceback_'\n",
      "\n",
      "During handling of the above exception, another exception occurred:\n",
      "\n",
      "Traceback (most recent call last):\n",
      "  File \"C:\\Users\\HP\\Anaconda3\\lib\\site-packages\\IPython\\core\\ultratb.py\", line 1101, in get_records\n",
      "    return _fixed_getinnerframes(etb, number_of_lines_of_context, tb_offset)\n",
      "  File \"C:\\Users\\HP\\Anaconda3\\lib\\site-packages\\IPython\\core\\ultratb.py\", line 248, in wrapped\n",
      "    return f(*args, **kwargs)\n",
      "  File \"C:\\Users\\HP\\Anaconda3\\lib\\site-packages\\IPython\\core\\ultratb.py\", line 281, in _fixed_getinnerframes\n",
      "    records = fix_frame_records_filenames(inspect.getinnerframes(etb, context))\n",
      "  File \"C:\\Users\\HP\\Anaconda3\\lib\\inspect.py\", line 1502, in getinnerframes\n",
      "    frameinfo = (tb.tb_frame,) + getframeinfo(tb, context)\n",
      "  File \"C:\\Users\\HP\\Anaconda3\\lib\\inspect.py\", line 1460, in getframeinfo\n",
      "    filename = getsourcefile(frame) or getfile(frame)\n",
      "  File \"C:\\Users\\HP\\Anaconda3\\lib\\inspect.py\", line 696, in getsourcefile\n",
      "    if getattr(getmodule(object, filename), '__loader__', None) is not None:\n",
      "  File \"C:\\Users\\HP\\Anaconda3\\lib\\inspect.py\", line 733, in getmodule\n",
      "    if ismodule(module) and hasattr(module, '__file__'):\n",
      "  File \"C:\\Users\\HP\\Anaconda3\\lib\\site-packages\\tensorflow\\__init__.py\", line 50, in __getattr__\n",
      "    module = self._load()\n",
      "  File \"C:\\Users\\HP\\Anaconda3\\lib\\site-packages\\tensorflow\\__init__.py\", line 44, in _load\n",
      "    module = _importlib.import_module(self.__name__)\n",
      "  File \"C:\\Users\\HP\\Anaconda3\\lib\\importlib\\__init__.py\", line 127, in import_module\n",
      "    return _bootstrap._gcd_import(name[level:], package, level)\n",
      "  File \"<frozen importlib._bootstrap>\", line 1006, in _gcd_import\n",
      "  File \"<frozen importlib._bootstrap>\", line 983, in _find_and_load\n",
      "  File \"<frozen importlib._bootstrap>\", line 965, in _find_and_load_unlocked\n",
      "ModuleNotFoundError: No module named 'tensorflow_core.estimator'\n"
     ]
    }
   ],
   "source": [
    "history = model.fit_generator(\n",
    "    train_Aug.flow(X_train, Y_train, batch_size=32),\n",
    "    steps_per_epoch=len(X_train)//32,\n",
    "    validation_data=valid_Aug.flow(X_test, Y_test),\n",
    "    validation_steps=len(X_test)//32,\n",
    "    epochs=epochs\n",
    ")\n"
   ]
  },
  {
   "cell_type": "code",
   "execution_count": 65,
   "id": "0967f89d",
   "metadata": {},
   "outputs": [],
   "source": [
    "# Save Model\n",
    "\n",
    "import pickle\n",
    "\n",
    "model.save(output_model)\n",
    "lbinarizer = open(r\"KD_classification_model\\KD_classification_binarizer.pickle\", \"wb\")\n",
    "lbinarizer.write(pickle.dumps(lb))\n",
    "lbinarizer.close()"
   ]
  },
  {
   "cell_type": "code",
   "execution_count": null,
   "id": "5a69bf47",
   "metadata": {},
   "outputs": [],
   "source": []
  }
 ],
 "metadata": {
  "kernelspec": {
   "display_name": "Python 3",
   "language": "python",
   "name": "python3"
  },
  "language_info": {
   "codemirror_mode": {
    "name": "ipython",
    "version": 3
   },
   "file_extension": ".py",
   "mimetype": "text/x-python",
   "name": "python",
   "nbconvert_exporter": "python",
   "pygments_lexer": "ipython3",
   "version": "3.7.3"
  }
 },
 "nbformat": 4,
 "nbformat_minor": 5
}
