{
 "cells": [
  {
   "cell_type": "code",
   "execution_count": 1,
   "id": "db3c56f0",
   "metadata": {},
   "outputs": [
    {
     "name": "stderr",
     "output_type": "stream",
     "text": [
      "Using TensorFlow backend.\n"
     ]
    }
   ],
   "source": [
    "from keras.models import load_model\n",
    "from collections import deque\n",
    "import numpy as np\n",
    "import pickle\n",
    "import cv2\n",
    "import os"
   ]
  },
  {
   "cell_type": "code",
   "execution_count": 2,
   "id": "9d1e7d8c",
   "metadata": {},
   "outputs": [
    {
     "name": "stderr",
     "output_type": "stream",
     "text": [
      "C:\\Users\\HP\\Anaconda3\\lib\\site-packages\\sklearn\\base.py:315: UserWarning: Trying to unpickle estimator LabelBinarizer from version 0.24.1 when using version 0.24.2. This might lead to breaking code or invalid results. Use at your own risk.\n",
      "  UserWarning)\n"
     ]
    }
   ],
   "source": [
    "model = load_model(r\"KD_classification_model\\classification_model\")\n",
    "lb = pickle.loads(open(r\"KD_classification_model\\KD_classification_binarizer.pickle\",\"rb\").read())\n",
    "video_output = r\"KD_classification_model\\classified_output.mp4\"\n",
    "\n",
    "mean = np.array([123.68, 116.779, 103.939][::1], dtype=\"float32\")\n",
    "queue = deque(maxlen=128)\n"
   ]
  },
  {
   "cell_type": "code",
   "execution_count": null,
   "id": "88de8d47",
   "metadata": {},
   "outputs": [
    {
     "name": "stdout",
     "output_type": "stream",
     "text": [
      "All Frames Done\n",
      "Finalizing...\n"
     ]
    },
    {
     "name": "stderr",
     "output_type": "stream",
     "text": [
      "ERROR:root:Internal Python error in the inspect module.\n",
      "Below is the traceback from this internal error.\n",
      "\n",
      "ERROR:root:Internal Python error in the inspect module.\n",
      "Below is the traceback from this internal error.\n",
      "\n",
      "ERROR:root:Internal Python error in the inspect module.\n",
      "Below is the traceback from this internal error.\n",
      "\n"
     ]
    },
    {
     "name": "stdout",
     "output_type": "stream",
     "text": [
      "Traceback (most recent call last):\n",
      "  File \"C:\\Users\\HP\\Anaconda3\\lib\\site-packages\\IPython\\core\\interactiveshell.py\", line 3437, in run_code\n",
      "    exec(code_obj, self.user_global_ns, self.user_ns)\n",
      "  File \"<ipython-input-3-adbb9046e1a1>\", line 71, in <module>\n",
      "    writer.release()\n",
      "AttributeError: 'NoneType' object has no attribute 'release'\n",
      "\n",
      "During handling of the above exception, another exception occurred:\n",
      "\n",
      "Traceback (most recent call last):\n",
      "  File \"C:\\Users\\HP\\Anaconda3\\lib\\site-packages\\IPython\\core\\interactiveshell.py\", line 2061, in showtraceback\n",
      "    stb = value._render_traceback_()\n",
      "AttributeError: 'AttributeError' object has no attribute '_render_traceback_'\n",
      "\n",
      "During handling of the above exception, another exception occurred:\n",
      "\n",
      "Traceback (most recent call last):\n",
      "  File \"C:\\Users\\HP\\Anaconda3\\lib\\site-packages\\IPython\\core\\ultratb.py\", line 1101, in get_records\n",
      "    return _fixed_getinnerframes(etb, number_of_lines_of_context, tb_offset)\n",
      "  File \"C:\\Users\\HP\\Anaconda3\\lib\\site-packages\\IPython\\core\\ultratb.py\", line 248, in wrapped\n",
      "    return f(*args, **kwargs)\n",
      "  File \"C:\\Users\\HP\\Anaconda3\\lib\\site-packages\\IPython\\core\\ultratb.py\", line 281, in _fixed_getinnerframes\n",
      "    records = fix_frame_records_filenames(inspect.getinnerframes(etb, context))\n",
      "  File \"C:\\Users\\HP\\Anaconda3\\lib\\inspect.py\", line 1502, in getinnerframes\n",
      "    frameinfo = (tb.tb_frame,) + getframeinfo(tb, context)\n",
      "  File \"C:\\Users\\HP\\Anaconda3\\lib\\inspect.py\", line 1460, in getframeinfo\n",
      "    filename = getsourcefile(frame) or getfile(frame)\n",
      "  File \"C:\\Users\\HP\\Anaconda3\\lib\\inspect.py\", line 696, in getsourcefile\n",
      "    if getattr(getmodule(object, filename), '__loader__', None) is not None:\n",
      "  File \"C:\\Users\\HP\\Anaconda3\\lib\\inspect.py\", line 733, in getmodule\n",
      "    if ismodule(module) and hasattr(module, '__file__'):\n",
      "  File \"C:\\Users\\HP\\Anaconda3\\lib\\site-packages\\tensorflow\\__init__.py\", line 50, in __getattr__\n",
      "    module = self._load()\n",
      "  File \"C:\\Users\\HP\\Anaconda3\\lib\\site-packages\\tensorflow\\__init__.py\", line 44, in _load\n",
      "    module = _importlib.import_module(self.__name__)\n",
      "  File \"C:\\Users\\HP\\Anaconda3\\lib\\importlib\\__init__.py\", line 127, in import_module\n",
      "    return _bootstrap._gcd_import(name[level:], package, level)\n",
      "  File \"<frozen importlib._bootstrap>\", line 1006, in _gcd_import\n",
      "  File \"<frozen importlib._bootstrap>\", line 983, in _find_and_load\n",
      "  File \"<frozen importlib._bootstrap>\", line 965, in _find_and_load_unlocked\n",
      "ModuleNotFoundError: No module named 'tensorflow_core.estimator'\n",
      "Traceback (most recent call last):\n",
      "  File \"C:\\Users\\HP\\Anaconda3\\lib\\site-packages\\IPython\\core\\interactiveshell.py\", line 3437, in run_code\n",
      "    exec(code_obj, self.user_global_ns, self.user_ns)\n",
      "  File \"<ipython-input-3-adbb9046e1a1>\", line 71, in <module>\n",
      "    writer.release()\n",
      "AttributeError: 'NoneType' object has no attribute 'release'\n",
      "\n",
      "During handling of the above exception, another exception occurred:\n",
      "\n",
      "Traceback (most recent call last):\n",
      "  File \"C:\\Users\\HP\\Anaconda3\\lib\\site-packages\\IPython\\core\\interactiveshell.py\", line 2061, in showtraceback\n",
      "    stb = value._render_traceback_()\n",
      "AttributeError: 'AttributeError' object has no attribute '_render_traceback_'\n",
      "\n",
      "During handling of the above exception, another exception occurred:\n",
      "\n",
      "Traceback (most recent call last):\n",
      "  File \"C:\\Users\\HP\\Anaconda3\\lib\\site-packages\\IPython\\core\\interactiveshell.py\", line 3357, in run_ast_nodes\n",
      "    if (await self.run_code(code, result,  async_=asy)):\n",
      "  File \"C:\\Users\\HP\\Anaconda3\\lib\\site-packages\\IPython\\core\\interactiveshell.py\", line 3454, in run_code\n",
      "    self.showtraceback(running_compiled_code=True)\n",
      "  File \"C:\\Users\\HP\\Anaconda3\\lib\\site-packages\\IPython\\core\\interactiveshell.py\", line 2064, in showtraceback\n",
      "    value, tb, tb_offset=tb_offset)\n",
      "  File \"C:\\Users\\HP\\Anaconda3\\lib\\site-packages\\IPython\\core\\ultratb.py\", line 1368, in structured_traceback\n",
      "    self, etype, value, tb, tb_offset, number_of_lines_of_context)\n",
      "  File \"C:\\Users\\HP\\Anaconda3\\lib\\site-packages\\IPython\\core\\ultratb.py\", line 1268, in structured_traceback\n",
      "    self, etype, value, tb, tb_offset, number_of_lines_of_context\n",
      "  File \"C:\\Users\\HP\\Anaconda3\\lib\\site-packages\\IPython\\core\\ultratb.py\", line 1125, in structured_traceback\n",
      "    tb_offset)\n",
      "  File \"C:\\Users\\HP\\Anaconda3\\lib\\site-packages\\IPython\\core\\ultratb.py\", line 1082, in format_exception_as_a_whole\n",
      "    last_unique, recursion_repeat = find_recursion(orig_etype, evalue, records)\n",
      "  File \"C:\\Users\\HP\\Anaconda3\\lib\\site-packages\\IPython\\core\\ultratb.py\", line 382, in find_recursion\n",
      "    return len(records), 0\n",
      "TypeError: object of type 'NoneType' has no len()\n",
      "\n",
      "During handling of the above exception, another exception occurred:\n",
      "\n",
      "Traceback (most recent call last):\n",
      "  File \"C:\\Users\\HP\\Anaconda3\\lib\\site-packages\\IPython\\core\\interactiveshell.py\", line 2061, in showtraceback\n",
      "    stb = value._render_traceback_()\n",
      "AttributeError: 'TypeError' object has no attribute '_render_traceback_'\n",
      "\n",
      "During handling of the above exception, another exception occurred:\n",
      "\n",
      "Traceback (most recent call last):\n",
      "  File \"C:\\Users\\HP\\Anaconda3\\lib\\site-packages\\IPython\\core\\ultratb.py\", line 1101, in get_records\n",
      "    return _fixed_getinnerframes(etb, number_of_lines_of_context, tb_offset)\n",
      "  File \"C:\\Users\\HP\\Anaconda3\\lib\\site-packages\\IPython\\core\\ultratb.py\", line 248, in wrapped\n",
      "    return f(*args, **kwargs)\n",
      "  File \"C:\\Users\\HP\\Anaconda3\\lib\\site-packages\\IPython\\core\\ultratb.py\", line 281, in _fixed_getinnerframes\n",
      "    records = fix_frame_records_filenames(inspect.getinnerframes(etb, context))\n",
      "  File \"C:\\Users\\HP\\Anaconda3\\lib\\inspect.py\", line 1502, in getinnerframes\n",
      "    frameinfo = (tb.tb_frame,) + getframeinfo(tb, context)\n",
      "  File \"C:\\Users\\HP\\Anaconda3\\lib\\inspect.py\", line 1460, in getframeinfo\n",
      "    filename = getsourcefile(frame) or getfile(frame)\n",
      "  File \"C:\\Users\\HP\\Anaconda3\\lib\\inspect.py\", line 696, in getsourcefile\n",
      "    if getattr(getmodule(object, filename), '__loader__', None) is not None:\n",
      "  File \"C:\\Users\\HP\\Anaconda3\\lib\\inspect.py\", line 733, in getmodule\n",
      "    if ismodule(module) and hasattr(module, '__file__'):\n",
      "  File \"C:\\Users\\HP\\Anaconda3\\lib\\site-packages\\tensorflow\\__init__.py\", line 50, in __getattr__\n",
      "    module = self._load()\n",
      "  File \"C:\\Users\\HP\\Anaconda3\\lib\\site-packages\\tensorflow\\__init__.py\", line 44, in _load\n",
      "    module = _importlib.import_module(self.__name__)\n",
      "  File \"C:\\Users\\HP\\Anaconda3\\lib\\importlib\\__init__.py\", line 127, in import_module\n",
      "    return _bootstrap._gcd_import(name[level:], package, level)\n",
      "  File \"<frozen importlib._bootstrap>\", line 1006, in _gcd_import\n",
      "  File \"<frozen importlib._bootstrap>\", line 983, in _find_and_load\n",
      "  File \"<frozen importlib._bootstrap>\", line 965, in _find_and_load_unlocked\n",
      "ModuleNotFoundError: No module named 'tensorflow_core.estimator'\n",
      "Traceback (most recent call last):\n",
      "  File \"C:\\Users\\HP\\Anaconda3\\lib\\site-packages\\IPython\\core\\interactiveshell.py\", line 3437, in run_code\n",
      "    exec(code_obj, self.user_global_ns, self.user_ns)\n",
      "  File \"<ipython-input-3-adbb9046e1a1>\", line 71, in <module>\n",
      "    writer.release()\n",
      "AttributeError: 'NoneType' object has no attribute 'release'\n",
      "\n",
      "During handling of the above exception, another exception occurred:\n",
      "\n",
      "Traceback (most recent call last):\n",
      "  File \"C:\\Users\\HP\\Anaconda3\\lib\\site-packages\\IPython\\core\\interactiveshell.py\", line 2061, in showtraceback\n",
      "    stb = value._render_traceback_()\n",
      "AttributeError: 'AttributeError' object has no attribute '_render_traceback_'\n",
      "\n",
      "During handling of the above exception, another exception occurred:\n",
      "\n",
      "Traceback (most recent call last):\n",
      "  File \"C:\\Users\\HP\\Anaconda3\\lib\\site-packages\\IPython\\core\\interactiveshell.py\", line 3357, in run_ast_nodes\n",
      "    if (await self.run_code(code, result,  async_=asy)):\n",
      "  File \"C:\\Users\\HP\\Anaconda3\\lib\\site-packages\\IPython\\core\\interactiveshell.py\", line 3454, in run_code\n",
      "    self.showtraceback(running_compiled_code=True)\n",
      "  File \"C:\\Users\\HP\\Anaconda3\\lib\\site-packages\\IPython\\core\\interactiveshell.py\", line 2064, in showtraceback\n",
      "    value, tb, tb_offset=tb_offset)\n",
      "  File \"C:\\Users\\HP\\Anaconda3\\lib\\site-packages\\IPython\\core\\ultratb.py\", line 1368, in structured_traceback\n",
      "    self, etype, value, tb, tb_offset, number_of_lines_of_context)\n",
      "  File \"C:\\Users\\HP\\Anaconda3\\lib\\site-packages\\IPython\\core\\ultratb.py\", line 1268, in structured_traceback\n",
      "    self, etype, value, tb, tb_offset, number_of_lines_of_context\n",
      "  File \"C:\\Users\\HP\\Anaconda3\\lib\\site-packages\\IPython\\core\\ultratb.py\", line 1125, in structured_traceback\n",
      "    tb_offset)\n",
      "  File \"C:\\Users\\HP\\Anaconda3\\lib\\site-packages\\IPython\\core\\ultratb.py\", line 1082, in format_exception_as_a_whole\n",
      "    last_unique, recursion_repeat = find_recursion(orig_etype, evalue, records)\n",
      "  File \"C:\\Users\\HP\\Anaconda3\\lib\\site-packages\\IPython\\core\\ultratb.py\", line 382, in find_recursion\n",
      "    return len(records), 0\n",
      "TypeError: object of type 'NoneType' has no len()\n",
      "\n",
      "During handling of the above exception, another exception occurred:\n",
      "\n",
      "Traceback (most recent call last):\n",
      "  File \"C:\\Users\\HP\\Anaconda3\\lib\\site-packages\\IPython\\core\\interactiveshell.py\", line 2061, in showtraceback\n",
      "    stb = value._render_traceback_()\n",
      "AttributeError: 'TypeError' object has no attribute '_render_traceback_'\n",
      "\n",
      "During handling of the above exception, another exception occurred:\n",
      "\n",
      "Traceback (most recent call last):\n",
      "  File \"C:\\Users\\HP\\Anaconda3\\lib\\site-packages\\IPython\\core\\interactiveshell.py\", line 2940, in _run_cell\n",
      "    return runner(coro)\n",
      "  File \"C:\\Users\\HP\\Anaconda3\\lib\\site-packages\\IPython\\core\\async_helpers.py\", line 68, in _pseudo_sync_runner\n",
      "    coro.send(None)\n",
      "  File \"C:\\Users\\HP\\Anaconda3\\lib\\site-packages\\IPython\\core\\interactiveshell.py\", line 3166, in run_cell_async\n",
      "    interactivity=interactivity, compiler=compiler, result=result)\n",
      "  File \"C:\\Users\\HP\\Anaconda3\\lib\\site-packages\\IPython\\core\\interactiveshell.py\", line 3376, in run_ast_nodes\n",
      "    self.showtraceback()\n",
      "  File \"C:\\Users\\HP\\Anaconda3\\lib\\site-packages\\IPython\\core\\interactiveshell.py\", line 2064, in showtraceback\n",
      "    value, tb, tb_offset=tb_offset)\n",
      "  File \"C:\\Users\\HP\\Anaconda3\\lib\\site-packages\\IPython\\core\\ultratb.py\", line 1368, in structured_traceback\n",
      "    self, etype, value, tb, tb_offset, number_of_lines_of_context)\n",
      "  File \"C:\\Users\\HP\\Anaconda3\\lib\\site-packages\\IPython\\core\\ultratb.py\", line 1268, in structured_traceback\n",
      "    self, etype, value, tb, tb_offset, number_of_lines_of_context\n",
      "  File \"C:\\Users\\HP\\Anaconda3\\lib\\site-packages\\IPython\\core\\ultratb.py\", line 1143, in structured_traceback\n",
      "    chained_exceptions_tb_offset)\n",
      "  File \"C:\\Users\\HP\\Anaconda3\\lib\\site-packages\\IPython\\core\\ultratb.py\", line 1082, in format_exception_as_a_whole\n",
      "    last_unique, recursion_repeat = find_recursion(orig_etype, evalue, records)\n",
      "  File \"C:\\Users\\HP\\Anaconda3\\lib\\site-packages\\IPython\\core\\ultratb.py\", line 382, in find_recursion\n",
      "    return len(records), 0\n",
      "TypeError: object of type 'NoneType' has no len()\n",
      "\n",
      "During handling of the above exception, another exception occurred:\n",
      "\n",
      "Traceback (most recent call last):\n",
      "  File \"C:\\Users\\HP\\Anaconda3\\lib\\site-packages\\IPython\\core\\interactiveshell.py\", line 2061, in showtraceback\n",
      "    stb = value._render_traceback_()\n",
      "AttributeError: 'TypeError' object has no attribute '_render_traceback_'\n",
      "\n",
      "During handling of the above exception, another exception occurred:\n",
      "\n",
      "Traceback (most recent call last):\n",
      "  File \"C:\\Users\\HP\\Anaconda3\\lib\\site-packages\\IPython\\core\\ultratb.py\", line 1101, in get_records\n",
      "    return _fixed_getinnerframes(etb, number_of_lines_of_context, tb_offset)\n",
      "  File \"C:\\Users\\HP\\Anaconda3\\lib\\site-packages\\IPython\\core\\ultratb.py\", line 248, in wrapped\n",
      "    return f(*args, **kwargs)\n",
      "  File \"C:\\Users\\HP\\Anaconda3\\lib\\site-packages\\IPython\\core\\ultratb.py\", line 281, in _fixed_getinnerframes\n",
      "    records = fix_frame_records_filenames(inspect.getinnerframes(etb, context))\n",
      "  File \"C:\\Users\\HP\\Anaconda3\\lib\\inspect.py\", line 1502, in getinnerframes\n",
      "    frameinfo = (tb.tb_frame,) + getframeinfo(tb, context)\n",
      "  File \"C:\\Users\\HP\\Anaconda3\\lib\\inspect.py\", line 1460, in getframeinfo\n",
      "    filename = getsourcefile(frame) or getfile(frame)\n",
      "  File \"C:\\Users\\HP\\Anaconda3\\lib\\inspect.py\", line 696, in getsourcefile\n",
      "    if getattr(getmodule(object, filename), '__loader__', None) is not None:\n",
      "  File \"C:\\Users\\HP\\Anaconda3\\lib\\inspect.py\", line 733, in getmodule\n",
      "    if ismodule(module) and hasattr(module, '__file__'):\n",
      "  File \"C:\\Users\\HP\\Anaconda3\\lib\\site-packages\\tensorflow\\__init__.py\", line 50, in __getattr__\n",
      "    module = self._load()\n",
      "  File \"C:\\Users\\HP\\Anaconda3\\lib\\site-packages\\tensorflow\\__init__.py\", line 44, in _load\n",
      "    module = _importlib.import_module(self.__name__)\n",
      "  File \"C:\\Users\\HP\\Anaconda3\\lib\\importlib\\__init__.py\", line 127, in import_module\n",
      "    return _bootstrap._gcd_import(name[level:], package, level)\n",
      "  File \"<frozen importlib._bootstrap>\", line 1006, in _gcd_import\n",
      "  File \"<frozen importlib._bootstrap>\", line 983, in _find_and_load\n",
      "  File \"<frozen importlib._bootstrap>\", line 965, in _find_and_load_unlocked\n",
      "ModuleNotFoundError: No module named 'tensorflow_core.estimator'\n"
     ]
    }
   ],
   "source": [
    "capture_video = cv2.VideoCapture(r\"KD_classification_model\\5D_5K.mp4\")\n",
    "writer = None\n",
    "(width, height) = (None, None)\n",
    "\n",
    "\n",
    "save_path = os.path.join(\"output_frames\", \"\")\n",
    "xx = 0\n",
    "\n",
    "\n",
    "while True:\n",
    "    (taken, frame) = capture_video.read()\n",
    "    \n",
    "    if not taken:\n",
    "        print(\"All Frames Done\")\n",
    "        break\n",
    "    if width is None or height is None:\n",
    "        (width, height) = frame.shape[:2]\n",
    "    \n",
    "    \n",
    "    # Keep a copy of the frame\n",
    "    output = frame.copy()\n",
    "    \n",
    "    frame = cv2.cvtColor(frame, cv2.COLOR_BGR2RGB)\n",
    "    frame = cv2.resize(frame, (224,224)).astype(\"float32\")\n",
    "    frame -= mean\n",
    "    \n",
    "    # Predict each frame\n",
    "    pred = model.predict(np.expand_dims(frame, axis=0))[0]\n",
    "    \n",
    "    \n",
    "    # Rolling Averaging the prediction\n",
    "    queue.append(pred)\n",
    "    result = np.array(queue).mean(axis=0)\n",
    "    i = np.argmax(result)\n",
    "    label = lb.classes_[i]\n",
    "    \n",
    "    \n",
    "    # Write the predicted lable on the original copied frame\n",
    "    text = \"Score : {}\".format(label)\n",
    "    cv2.putText(output, text, (45,60), cv2.FONT_HERSHEY_SIMPLEX, 1, (255,0,0), 4)\n",
    "    \n",
    "    \n",
    "    '''\n",
    "    # Initialize video writer\n",
    "    if writer is None:\n",
    "        fourcc = cv2.VideoWriter_fourcc(*\"MJPG\")\n",
    "        writer = cv2.VideoWriter(video_output, fourcc, 30, (width, height), True)\n",
    "        print(\"Video Writer Ready\")\n",
    "    \n",
    "    writer.write(output)\n",
    "    '''\n",
    "    \n",
    "    \n",
    "    # Save the frames\n",
    "    filename = save_path + str(xx) + \".png\"\n",
    "    cv2.imwrite(filename, output)\n",
    "    xx = xx+1\n",
    "    \n",
    "    \n",
    "    # Show running frames\n",
    "    cv2.imshow(\"In progress frame by frame\", output)\n",
    "    \n",
    "    key = cv2.waitKey(1) & 0xFF\n",
    "        \n",
    "    if key == ord(\"q\"):\n",
    "        break\n",
    "    \n",
    "\n",
    "print(\"Finalizing...\")\n",
    "\n",
    "writer.release()\n",
    "capture_video.release()\n",
    "cv2.destroyAllWindows()\n",
    "\n",
    "print(\"Done\")\n"
   ]
  },
  {
   "cell_type": "code",
   "execution_count": 3,
   "id": "7c6baffd",
   "metadata": {},
   "outputs": [
    {
     "name": "stdout",
     "output_type": "stream",
     "text": [
      "ERROR! Session/line number was not unique in database. History logging moved to new session 280\n"
     ]
    }
   ],
   "source": [
    "# Create the output video\n",
    "\n",
    "import glob\n",
    "import re\n",
    " \n",
    "img_array = []\n",
    "numbers = re.compile(r'(\\d+)')\n",
    "\n",
    "def numericalSort(value):\n",
    "    parts = numbers.split(value)\n",
    "    parts[1::2] = map(int, parts[1::2])\n",
    "    return parts\n",
    "\n",
    "\n",
    "for filename in sorted(glob.glob('D:/Opus Project/output_frames/*.png'), key=numericalSort):\n",
    "    img = cv2.imread(filename)\n",
    "    height, width, layers = img.shape\n",
    "    size = (width,height)\n",
    "    img_array.append(img)\n",
    "\n",
    "\n",
    "out = cv2.VideoWriter('output_video.avi',cv2.VideoWriter_fourcc(*'DIVX'), 15, size)\n",
    " \n",
    "for i in range(len(img_array)):\n",
    "    out.write(img_array[i])\n",
    "\n",
    "out.release()\n"
   ]
  },
  {
   "cell_type": "code",
   "execution_count": null,
   "id": "bf046255",
   "metadata": {},
   "outputs": [],
   "source": []
  }
 ],
 "metadata": {
  "kernelspec": {
   "display_name": "Python 3",
   "language": "python",
   "name": "python3"
  },
  "language_info": {
   "codemirror_mode": {
    "name": "ipython",
    "version": 3
   },
   "file_extension": ".py",
   "mimetype": "text/x-python",
   "name": "python",
   "nbconvert_exporter": "python",
   "pygments_lexer": "ipython3",
   "version": "3.7.3"
  }
 },
 "nbformat": 4,
 "nbformat_minor": 5
}
